<robot name = "myemojihair_Long29_Male">
<link name="head_JNT">
   <interial>
       <mass value="5.0" />
   </interial>
    <collision>
        <geometry>
            <cylinder radius="0.171667" length="0.503874" />
        </geometry>
    </collision>
</link>
<link name="hair_01_JNT">
   <interial>
       <mass value="0.01" />
   </interial>
    <collision>
        <geometry>
           <box size="1.000000 1.000000 1.000000" />
        </geometry>
    </collision>
</link>
<joint name="joint_hair_01_JNT" type="floating" >
    <parent link="head_JNT" />
    <child link="hair_01_JNT" />
    <dynamics friction="0.000000" damping="0.040000" />
    <origin xyz="0.024220 0.018929 -0.004564" rpy="-34.457432 12.001139 -12.062184" />
</joint>
<link name="hair_01_01_JNT">
   <interial>
       <mass value="0.01" />
   </interial>
    <collision>
        <geometry>
           <box size="0.103646 0.059286 0.060867" />
        </geometry>
    </collision>
</link>
<joint name="joint_hair_01_01_JNT" type="floating" >
    <parent link="hair_01_JNT" />
    <child link="hair_01_01_JNT" />
    <dynamics friction="0.000000" damping="0.040000" />
    <origin xyz="-0.007462 -0.040244 0.017889" rpy="36.283852 -5.260893 19.055040" />
</joint>
<link name="hair_01_02_JNT">
   <interial>
       <mass value="0.01" />
   </interial>
    <collision>
        <geometry>
           <box size="0.100000 0.066945 0.100000" />
        </geometry>
    </collision>
</link>
<joint name="joint_hair_01_02_JNT" type="floating" >
    <parent link="hair_01_01_JNT" />
    <child link="hair_01_02_JNT" />
    <dynamics friction="0.000000" damping="0.040000" />
    <origin xyz="0.007563 -0.015824 0.010678" rpy="-3.644172 3.087821 -2.064760" />
</joint>
<link name="hair_02_JNT">
   <interial>
       <mass value="0.01" />
   </interial>
    <collision>
        <geometry>
           <box size="0.122910 0.065588 0.063352" />
        </geometry>
    </collision>
</link>
<joint name="joint_hair_02_JNT" type="floating" >
    <parent link="head_JNT" />
    <child link="hair_02_JNT" />
    <dynamics friction="0.000000" damping="0.040000" />
    <origin xyz="0.028773 0.011384 -0.028946" rpy="-16.662157 -13.502582 -10.773018" />
</joint>
<link name="hair_02_01_JNT">
   <interial>
       <mass value="0.01" />
   </interial>
    <collision>
        <geometry>
           <box size="0.123627 0.071958 0.054122" />
        </geometry>
    </collision>
</link>
<joint name="joint_hair_02_01_JNT" type="floating" >
    <parent link="hair_02_JNT" />
    <child link="hair_02_01_JNT" />
    <dynamics friction="0.000000" damping="0.040000" />
    <origin xyz="-0.010744 -0.050459 0.015176" rpy="16.802267 10.918856 4.538116" />
</joint>
<link name="hair_02_02_JNT">
   <interial>
       <mass value="0.01" />
   </interial>
    <collision>
        <geometry>
           <box size="0.097416 0.050429 0.040728" />
        </geometry>
    </collision>
</link>
<joint name="joint_hair_02_02_JNT" type="floating" >
    <parent link="hair_02_01_JNT" />
    <child link="hair_02_02_JNT" />
    <dynamics friction="0.000000" damping="0.040000" />
    <origin xyz="-0.002559 -0.023522 0.003164" rpy="1.656937 5.027170 1.966421" />
</joint>
<link name="hair_03_JNT">
   <interial>
       <mass value="0.01" />
   </interial>
    <collision>
        <geometry>
           <box size="0.074002 0.065588 0.063352" />
        </geometry>
    </collision>
</link>
<joint name="joint_hair_03_JNT" type="floating" >
    <parent link="head_JNT" />
    <child link="hair_03_JNT" />
    <dynamics friction="0.000000" damping="0.040000" />
    <origin xyz="0.008288 0.027404 -0.047282" rpy="-1.198513 -13.988201 -5.719682" />
</joint>
<link name="hair_03_01_JNT">
   <interial>
       <mass value="0.01" />
   </interial>
    <collision>
        <geometry>
           <box size="0.085890 0.070175 0.054122" />
        </geometry>
    </collision>
</link>
<joint name="joint_hair_03_01_JNT" type="floating" >
    <parent link="hair_03_JNT" />
    <child link="hair_03_01_JNT" />
    <dynamics friction="0.000000" damping="0.040000" />
    <origin xyz="0.011053 -0.092308 0.021056" rpy="1.003631 -14.664025 11.274240" />
</joint>
<link name="hair_03_02_JNT">
   <interial>
       <mass value="0.01" />
   </interial>
    <collision>
        <geometry>
           <box size="0.082071 0.051662 0.047039" />
        </geometry>
    </collision>
</link>
<joint name="joint_hair_03_02_JNT" type="floating" >
    <parent link="hair_03_01_JNT" />
    <child link="hair_03_02_JNT" />
    <dynamics friction="0.000000" damping="0.040000" />
    <origin xyz="0.001394 -0.036355 0.016730" rpy="2.522924 6.285172 1.045495" />
</joint>
<link name="hair_04_JNT">
   <interial>
       <mass value="0.01" />
   </interial>
    <collision>
        <geometry>
           <box size="0.077194 0.065588 0.063352" />
        </geometry>
    </collision>
</link>
<joint name="joint_hair_04_JNT" type="floating" >
    <parent link="head_JNT" />
    <child link="hair_04_JNT" />
    <dynamics friction="0.000000" damping="0.040000" />
    <origin xyz="-0.023260 0.007525 -0.089279" rpy="8.497117 -10.388098 7.432651" />
</joint>
<link name="hair_04_01_JNT">
   <interial>
       <mass value="0.01" />
   </interial>
    <collision>
        <geometry>
           <box size="0.079377 0.068793 0.054122" />
        </geometry>
    </collision>
</link>
<joint name="joint_hair_04_01_JNT" type="floating" >
    <parent link="hair_04_JNT" />
    <child link="hair_04_01_JNT" />
    <dynamics friction="0.000000" damping="0.040000" />
    <origin xyz="-0.002189 -0.079375 0.019609" rpy="-3.731254 -12.103778 -10.615581" />
</joint>
<link name="hair_04_02_JNT">
   <interial>
       <mass value="0.01" />
   </interial>
    <collision>
        <geometry>
           <box size="0.087849 0.042491 0.040728" />
        </geometry>
    </collision>
</link>
<joint name="joint_hair_04_02_JNT" type="floating" >
    <parent link="hair_04_01_JNT" />
    <child link="hair_04_02_JNT" />
    <dynamics friction="0.000000" damping="0.040000" />
    <origin xyz="0.005530 -0.041298 0.010227" rpy="1.181131 -9.287937 5.515448" />
</joint>
<link name="hair_05_JNT">
   <interial>
       <mass value="0.01" />
   </interial>
    <collision>
        <geometry>
           <box size="0.075838 0.065588 0.041787" />
        </geometry>
    </collision>
</link>
<joint name="joint_hair_05_JNT" type="floating" >
    <parent link="head_JNT" />
    <child link="hair_05_JNT" />
    <dynamics friction="0.000000" damping="0.040000" />
    <origin xyz="-0.053388 0.015039 -0.041469" rpy="22.122511 -26.466848 14.351749" />
</joint>
<link name="hair_05_01_JNT">
   <interial>
       <mass value="0.01" />
   </interial>
    <collision>
        <geometry>
           <box size="0.092047 0.070704 0.054122" />
        </geometry>
    </collision>
</link>
<joint name="joint_hair_05_01_JNT" type="floating" >
    <parent link="hair_05_JNT" />
    <child link="hair_05_01_JNT" />
    <dynamics friction="0.000000" damping="0.040000" />
    <origin xyz="0.007170 -0.088832 -0.000131" rpy="-8.261026 14.359652 -1.293038" />
</joint>
<link name="hair_05_02_JNT">
   <interial>
       <mass value="0.01" />
   </interial>
    <collision>
        <geometry>
           <box size="0.089752 0.043866 0.040728" />
        </geometry>
    </collision>
</link>
<joint name="joint_hair_05_02_JNT" type="floating" >
    <parent link="hair_05_01_JNT" />
    <child link="hair_05_02_JNT" />
    <dynamics friction="0.000000" damping="0.040000" />
    <origin xyz="0.000326 -0.040389 -0.006885" rpy="-5.621805 15.238911 -1.515952" />
</joint>
<link name="hair_06_JNT">
   <interial>
       <mass value="0.01" />
   </interial>
    <collision>
        <geometry>
           <box size="1.000000 1.000000 1.000000" />
        </geometry>
    </collision>
</link>
<joint name="joint_hair_06_JNT" type="floating" >
    <parent link="head_JNT" />
    <child link="hair_06_JNT" />
    <dynamics friction="0.000000" damping="0.040000" />
    <origin xyz="-0.061150 0.025813 -0.003559" rpy="46.029663 17.864519 14.030622" />
</joint>
<link name="hair_06_01_JNT">
   <interial>
       <mass value="0.01" />
   </interial>
    <collision>
        <geometry>
           <box size="0.100000 0.072326 0.100000" />
        </geometry>
    </collision>
</link>
<joint name="joint_hair_06_01_JNT" type="floating" >
    <parent link="hair_06_JNT" />
    <child link="hair_06_01_JNT" />
    <dynamics friction="0.000000" damping="0.040000" />
    <origin xyz="0.031738 -0.011219 0.076471" rpy="-12.340368 -80.992996 -12.654504" />
</joint>
<link name="hair_06_02_JNT">
   <interial>
       <mass value="0.01" />
   </interial>
    <collision>
        <geometry>
           <box size="0.100000 0.062761 0.100000" />
        </geometry>
    </collision>
</link>
<joint name="joint_hair_06_02_JNT" type="floating" >
    <parent link="hair_06_01_JNT" />
    <child link="hair_06_02_JNT" />
    <dynamics friction="0.000000" damping="0.040000" />
    <origin xyz="0.106174 -0.001378 0.275615" rpy="-8.752030 -6.779328 5.495333" />
</joint>
<link name="r_earring_accessory_JNT">
   <interial>
       <mass value="0.01" />
   </interial>
    <collision>
        <geometry>
            <sphere radius="0.025000" />
        </geometry>
    </collision>
</link>
<joint name="joint_r_earring_accessory_JNT" type="floating" >
    <parent link="head_JNT" />
    <child link="r_earring_accessory_JNT" />
    <dynamics friction="0.000000" damping="0.040000" />
    <origin xyz="-0.115987 -0.034802 -0.002251" rpy="0.000000 0.000000 -0.000000" />
</joint>
<link name="l_earring_accessory_JNT">
   <interial>
       <mass value="0.01" />
   </interial>
    <collision>
        <geometry>
            <sphere radius="0.025000" />
        </geometry>
    </collision>
</link>
<joint name="joint_l_earring_accessory_JNT" type="floating" >
    <parent link="head_JNT" />
    <child link="l_earring_accessory_JNT" />
    <dynamics friction="0.000000" damping="0.040000" />
    <origin xyz="0.117393 -0.034802 -0.002251" rpy="0.000000 0.000000 -0.000000" />
</joint>
</robot>